Workbook
Name Master: #REF!
Name Sub_head: #REF!
Name NamedRange1: #REF!

Sheet YES Master 0264
B1: XX0264 | D1: Cust ID | E1: 33167514 | H1: 46258 | I1: =SUBTOTAL(9,I9:I236) -> 0 | J1: =SUBTOTAL(9,J9:J236) -> 10724949 | K1: =J1-I1 -> 10724949
A2: SL# | B2: QTR | C2: MONTH | D2: TXN DATE | E2: VALUE DATE | F2: TYPE | G2: DESCRIPTION | H2: REFERENCE | I2: DEBITS | J2: CREDITS | K2: BALANCE | L2: BUSINESS UNIT | M2: HEAD | N2: SUB HEAD | O2: RECO | P2: TYPE FOR RERA IDW | Q2: TCP Head | R2: CONCERN | S2: CUST ID | T2: APT# | U2: ACC REMARKS | V2: CRM REMARKS | W2: NARRATION | X2: Tax Rate | Y2: Bal as per AI | Z2: Check | AA2: Auth MB | AB2: Auth MK | AC2: Auth NM
A5: =ROW()-1 -> 4 | B5: =IFERROR("Q"&(INT(MOD(C5-4,12)/3)+1),"") -> Q2 | C5: =IFERROR(MONTH(DATEVALUE(D5)),"") -> 8 | D5: 17-Aug-2026 | E5: 17-Aug-2026 | G5: YIB-TPT-DWARKADHIS PROJECTS PVT LT D-TRANSFERFROM0264TO0477ONACCONTOFC USTOMER-045563400002477 | I5: 49426 | K5: =IFERROR(K6+J5-I5,"") -> 29079.78 | L5: Casa Romana | M5: Internal | O5: Reco | P5: Master to Free | Q5: Internal transfer | W5: =TRIM(IF(M5="Internal", IF(ISBLANK(G5), IF(LEN(G5)-LEN(SUBSTITUTE(G5,"-",""))>=3, "Fund Transfer: From x" & RIGHT(MID(G5, FIND("|", SUBSTITUTE(G5, "-", "|", 3)) + 1, LEN(G5)), 4) & " to YES MASTER 0264 (Ref: " & H5 & ") (Type: " & P5 & ") (BU: " & L5 & ") (Head: " & M5 & ")", "Fund Transfer: To YES MASTER 0264 (Ref: " & H5 & ") (Type: " & P5 & ") (BU: " & L5 & ") (Head: " & M5 & ")"), IF(LEN(G5)-LEN(SUBSTITUTE(G5,"-",""))>=3, "Fund Transfer: From YES MASTER 0264 to x" & RIGHT(MID(G5, FIND("|", SUBSTITUTE(G5, "-", "|", 3)) + 1, LEN(G5)), 4) & " (Ref: " & H5 & ") (Type: " & P5 & ") (BU: " & L5 & ") (Head: " & M5 & ")", "Fund Transfer: From YES MASTER 0264 (Ref: " & H5 & ") (Type: " & P5 & ") (BU: " & L5 & ") (Head: " & M5 & ")")), IF(NOT(ISBLANK(J5)), IF(P5="Customer Collection", "Receipt: For " & IF(ISBLANK(T5), "", "(Apt#: " & T5 & ") ") & "(Ref: " & H5 & ") (" & IF(ISNUMBER(SEARCH("NEFT",G5)), "NEFT:", IF(ISNUMBER(SEARCH("RTGS",G5)), "RTGS:", IF(ISNUMBER(SEARCH("IMPS",G5)), "IMPS:", ""))) & " " & IF(ISNUMBER(SEARCH("SOHNA ROAD", G5)), "", IFERROR(MID(G5, FIND("-", G5, FIND("-", G5) + 1) + 1, LEN(G5)), SUBSTITUTE(SUBSTITUTE(SUBSTITUTE(G5, "IMPS/", ""), "NEFT/", ""), "RTGS/", ""))) & ") (Type: " & P5 & ") (BU: " & L5 & ")", IF(LEN(G5)-LEN(SUBSTITUTE(G5,"-",""))>=3, "Receipt: From x" & RIGHT(MID(G5, FIND("|", SUBSTITUTE(G5, "-", "|", 3)) + 1, LEN(G5)), 4) & " towards " & IF(ISBLANK(U5), L5, U5) & IF(OR(L5="Cancellation", L5="Collection"), " Apt No " & T5, "") & " (Ref: " & H5 & ") (Type: " & P5 & ") (BU: " & L5 & ") (Head: " & M5 & ")" & IF(ISBLANK(T5), "", " (Apt#: " & T5 & ")"), "Receipt: Against " & IF(ISBLANK(U5), L5, U5) & IF(OR(L5="Cancellation", L5="Collection"), " Apt No " & T5, "") & " (Ref: " & H5 & ") (Type: " & P5 & ") (BU: " & L5 & ") (Head: " & M5 & ")" & IF(ISBLANK(T5), "", " (Apt#: " & T5 & ")"))), IF(LEN(G5)-LEN(SUBSTITUTE(G5,"-",""))>=3, "Payment: To x" & RIGHT(MID(G5, FIND("|", SUBSTITUTE(G5, "-", "|", 3)) + 1, LEN(G5)), 4) & " for " & IF(ISBLANK(U5), L5, U5) & " (Ref: " & H5 & ") (Type: " & P5 & ") (BU: " & L5 & ") (Head: " & M5 & ")" & IF(ISBLANK(T5), "", " (Apt#: " & T5 & ")"), "Payment: Disbursement for " & IF(ISBLANK(U5), "", IF(ISBLANK(U5), "", U5) & " ") & "(Ref: " & H5 & ") (Type: " & P5 & ") (BU: " & L5 & ") (Head: " & M5 & ")" & IF(ISBLANK(T5), "", " (Apt#: " & T5 & ")"))))) -> Fund Transfer: From YES MASTER 0264 to x2477 (Ref: ) (Type: Master to Free) (BU: Casa Romana) (Head: Internal) | Y5: 29079.78 | Z5: =IFERROR(ROUND(Y5-K5,2),"") -> 0
A6: =ROW()-1 -> 5 | B6: =IFERROR("Q"&(INT(MOD(C6-4,12)/3)+1),"") -> Q2 | C6: =IFERROR(MONTH(DATEVALUE(D6)),"") -> 8 | D6: 17-Aug-2026 | E6: 17-Aug-2026 | G6: YIB-TPT-DWARKADHIS PROJECTS PRIVATE LIMITED-TRANSFERFROM026 4TO0377ONACCONTOFCUSTOMER-04556320 0000377 | I6: 115326 | K6: =IFERROR(K7+J6-I6,"") -> 78505.78 | L6: Casa Romana | M6: Internal | O6: Entry | P6: Master 2 RERA | Q6: Internal transfer | W6: =TRIM(IF(M6="Internal", IF(ISBLANK(G6), IF(LEN(G6)-LEN(SUBSTITUTE(G6,"-",""))>=3, "Fund Transfer: From x" & RIGHT(MID(G6, FIND("|", SUBSTITUTE(G6, "-", "|", 3)) + 1, LEN(G6)), 4) & " to YES MASTER 0264 (Ref: " & H6 & ") (Type: " & P6 & ") (BU: " & L6 & ") (Head: " & M6 & ")", "Fund Transfer: To YES MASTER 0264 (Ref: " & H6 & ") (Type: " & P6 & ") (BU: " & L6 & ") (Head: " & M6 & ")"), IF(LEN(G6)-LEN(SUBSTITUTE(G6,"-",""))>=3, "Fund Transfer: From YES MASTER 0264 to x" & RIGHT(MID(G6, FIND("|", SUBSTITUTE(G6, "-", "|", 3)) + 1, LEN(G6)), 4) & " (Ref: " & H6 & ") (Type: " & P6 & ") (BU: " & L6 & ") (Head: " & M6 & ")", "Fund Transfer: From YES MASTER 0264 (Ref: " & H6 & ") (Type: " & P6 & ") (BU: " & L6 & ") (Head: " & M6 & ")")), IF(NOT(ISBLANK(J6)), IF(P6="Customer Collection", "Receipt: For " & IF(ISBLANK(T6), "", "(Apt#: " & T6 & ") ") & "(Ref: " & H6 & ") (" & IF(ISNUMBER(SEARCH("NEFT",G6)), "NEFT:", IF(ISNUMBER(SEARCH("RTGS",G6)), "RTGS:", IF(ISNUMBER(SEARCH("IMPS",G6)), "IMPS:", ""))) & " " & IF(ISNUMBER(SEARCH("SOHNA ROAD", G6)), "", IFERROR(MID(G6, FIND("-", G6, FIND("-", G6) + 1) + 1, LEN(G6)), SUBSTITUTE(SUBSTITUTE(SUBSTITUTE(G6, "IMPS/", ""), "NEFT/", ""), "RTGS/", ""))) & ") (Type: " & P6 & ") (BU: " & L6 & ")", IF(LEN(G6)-LEN(SUBSTITUTE(G6,"-",""))>=3, "Receipt: From x" & RIGHT(MID(G6, FIND("|", SUBSTITUTE(G6, "-", "|", 3)) + 1, LEN(G6)), 4) & " towards " & IF(ISBLANK(U6), L6, U6) & IF(OR(L6="Cancellation", L6="Collection"), " Apt No " & T6, "") & " (Ref: " & H6 & ") (Type: " & P6 & ") (BU: " & L6 & ") (Head: " & M6 & ")" & IF(ISBLANK(T6), "", " (Apt#: " & T6 & ")"), "Receipt: Against " & IF(ISBLANK(U6), L6, U6) & IF(OR(L6="Cancellation", L6="Collection"), " Apt No " & T6, "") & " (Ref: " & H6 & ") (Type: " & P6 & ") (BU: " & L6 & ") (Head: " & M6 & ")" & IF(ISBLANK(T6), "", " (Apt#: " & T6 & ")"))), IF(LEN(G6)-LEN(SUBSTITUTE(G6,"-",""))>=3, "Payment: To x" & RIGHT(MID(G6, FIND("|", SUBSTITUTE(G6, "-", "|", 3)) + 1, LEN(G6)), 4) & " for " & IF(ISBLANK(U6), L6, U6) & " (Ref: " & H6 & ") (Type: " & P6 & ") (BU: " & L6 & ") (Head: " & M6 & ")" & IF(ISBLANK(T6), "", " (Apt#: " & T6 & ")"), "Payment: Disbursement for " & IF(ISBLANK(U6), "", IF(ISBLANK(U6), "", U6) & " ") & "(Ref: " & H6 & ") (Type: " & P6 & ") (BU: " & L6 & ") (Head: " & M6 & ")" & IF(ISBLANK(T6), "", " (Apt#: " & T6 & ")"))))) -> Fund Transfer: From YES MASTER 0264 to x0377 (Ref: ) (Type: Master 2 RERA) (BU: Casa Romana) (Head: Internal) | Y6: 78505.78 | Z6: =IFERROR(ROUND(Y6-K6,2),"") -> 0
A7: =ROW()-1 -> 6 | B7: =IFERROR("Q"&(INT(MOD(C7-4,12)/3)+1),"") -> Q2 | C7: =IFERROR(MONTH(DATEVALUE(D7)),"") -> 8 | D7: 17-Aug-2026 | E7: 17-Aug-2026 | G7: IMPS/SUNITA SUNITA/XXX8258/ RRN:622911882764/STATE BANK OF INDIA | J7: 64752 | K7: =Y7 -> 193831.78 | L7: Casa Romana | M7: Collection | O7: Entry | P7: Customer Collection | Q7: Credit- no effect | T7: P-064 | V7: Adjust | W7: =TRIM(IF(M7="Internal", IF(ISBLANK(G7), IF(LEN(G7)-LEN(SUBSTITUTE(G7,"-",""))>=3, "Fund Transfer: From x" & RIGHT(MID(G7, FIND("|", SUBSTITUTE(G7, "-", "|", 3)) + 1, LEN(G7)), 4) & " to YES MASTER 0264 (Ref: " & H7 & ") (Type: " & P7 & ") (BU: " & L7 & ") (Head: " & M7 & ")", "Fund Transfer: To YES MASTER 0264 (Ref: " & H7 & ") (Type: " & P7 & ") (BU: " & L7 & ") (Head: " & M7 & ")"), IF(LEN(G7)-LEN(SUBSTITUTE(G7,"-",""))>=3, "Fund Transfer: From YES MASTER 0264 to x" & RIGHT(MID(G7, FIND("|", SUBSTITUTE(G7, "-", "|", 3)) + 1, LEN(G7)), 4) & " (Ref: " & H7 & ") (Type: " & P7 & ") (BU: " & L7 & ") (Head: " & M7 & ")", "Fund Transfer: From YES MASTER 0264 (Ref: " & H7 & ") (Type: " & P7 & ") (BU: " & L7 & ") (Head: " & M7 & ")")), IF(NOT(ISBLANK(J7)), IF(P7="Customer Collection", "Receipt: For " & IF(ISBLANK(T7), "", "(Apt#: " & T7 & ") ") & "(Ref: " & H7 & ") (" & IF(ISNUMBER(SEARCH("NEFT",G7)), "NEFT:", IF(ISNUMBER(SEARCH("RTGS",G7)), "RTGS:", IF(ISNUMBER(SEARCH("IMPS",G7)), "IMPS:", ""))) & " " & IF(ISNUMBER(SEARCH("SOHNA ROAD", G7)), "", IFERROR(MID(G7, FIND("-", G7, FIND("-", G7) + 1) + 1, LEN(G7)), SUBSTITUTE(SUBSTITUTE(SUBSTITUTE(G7, "IMPS/", ""), "NEFT/", ""), "RTGS/", ""))) & ") (Type: " & P7 & ") (BU: " & L7 & ")", IF(LEN(G7)-LEN(SUBSTITUTE(G7,"-",""))>=3, "Receipt: From x" & RIGHT(MID(G7, FIND("|", SUBSTITUTE(G7, "-", "|", 3)) + 1, LEN(G7)), 4) & " towards " & IF(ISBLANK(U7), L7, U7) & IF(OR(L7="Cancellation", L7="Collection"), " Apt No " & T7, "") & " (Ref: " & H7 & ") (Type: " & P7 & ") (BU: " & L7 & ") (Head: " & M7 & ")" & IF(ISBLANK(T7), "", " (Apt#: " & T7 & ")"), "Receipt: Against " & IF(ISBLANK(U7), L7, U7) & IF(OR(L7="Cancellation", L7="Collection"), " Apt No " & T7, "") & " (Ref: " & H7 & ") (Type: " & P7 & ") (BU: " & L7 & ") (Head: " & M7 & ")" & IF(ISBLANK(T7), "", " (Apt#: " & T7 & ")"))), IF(LEN(G7)-LEN(SUBSTITUTE(G7,"-",""))>=3, "Payment: To x" & RIGHT(MID(G7, FIND("|", SUBSTITUTE(G7, "-", "|", 3)) + 1, LEN(G7)), 4) & " for " & IF(ISBLANK(U7), L7, U7) & " (Ref: " & H7 & ") (Type: " & P7 & ") (BU: " & L7 & ") (Head: " & M7 & ")" & IF(ISBLANK(T7), "", " (Apt#: " & T7 & ")"), "Payment: Disbursement for " & IF(ISBLANK(U7), "", IF(ISBLANK(U7), "", U7) & " ") & "(Ref: " & H7 & ") (Type: " & P7 & ") (BU: " & L7 & ") (Head: " & M7 & ")" & IF(ISBLANK(T7), "", " (Apt#: " & T7 & ")"))))) -> Receipt: For (Apt#: P-064) (Ref: ) (IMPS: SUNITA SUNITA/XXX8258/ RRN:622911882764/STATE BANK OF INDIA) (Type: Customer Collection) (BU: Casa Romana) | Y7: 193831.78 | Z7: =IFERROR(ROUND(Y7-K7,2),"") -> 0
A8: 229 | B8: =IFERROR("Q"&(INT(MOD(C8-4,12)/3)+1),"") -> Q2 | C8: =IFERROR(MONTH(DATEVALUE(D8)),"") -> 8 | D8: 46250 | E8: 46250 | G8: IMPS/MRIGANKACHAKRABORTY/XXX7113/RRN:622810783912/AXIS BANK | H8: YBP6228654732943 | J8: 100000 | K8: =K9+J8-I8 -> 129078 | L8: Casa Romana | M8: Collection | O8: Entry | P8: Customer Collection | Q8: Credit- no effect | T8: P-071 | V8: Adjust | W8: =TRIM(IF(M8="Internal", IF(ISBLANK(G8), IF(LEN(G8)-LEN(SUBSTITUTE(G8,"-",""))>=3, "Fund Transfer: From x" & RIGHT(MID(G8, FIND("|", SUBSTITUTE(G8, "-", "|", 3)) + 1, LEN(G8)), 4) & " to YES MASTER 0264 (Ref: " & H8 & ") (Type: " & P8 & ") (BU: " & L8 & ") (Head: " & M8 & ")", "Fund Transfer: To YES MASTER 0264 (Ref: " & H8 & ") (Type: " & P8 & ") (BU: " & L8 & ") (Head: " & M8 & ")"), IF(LEN(G8)-LEN(SUBSTITUTE(G8,"-",""))>=3, "Fund Transfer: From YES MASTER 0264 to x" & RIGHT(MID(G8, FIND("|", SUBSTITUTE(G8, "-", "|", 3)) + 1, LEN(G8)), 4) & " (Ref: " & H8 & ") (Type: " & P8 & ") (BU: " & L8 & ") (Head: " & M8 & ")", "Fund Transfer: From YES MASTER 0264 (Ref: " & H8 & ") (Type: " & P8 & ") (BU: " & L8 & ") (Head: " & M8 & ")")), IF(NOT(ISBLANK(J8)), IF(P8="Customer Collection", "Receipt: For " & IF(ISBLANK(T8), "", "(Apt#: " & T8 & ") ") & "(Ref: " & H8 & ") (" & IF(ISNUMBER(SEARCH("NEFT",G8)), "NEFT:", IF(ISNUMBER(SEARCH("RTGS",G8)), "RTGS:", IF(ISNUMBER(SEARCH("IMPS",G8)), "IMPS:", ""))) & " " & IF(ISNUMBER(SEARCH("SOHNA ROAD", G8)), "", IFERROR(MID(G8, FIND("-", G8, FIND("-", G8) + 1) + 1, LEN(G8)), SUBSTITUTE(SUBSTITUTE(SUBSTITUTE(G8, "IMPS/", ""), "NEFT/", ""), "RTGS/", ""))) & ") (Type: " & P8 & ") (BU: " & L8 & ")", IF(LEN(G8)-LEN(SUBSTITUTE(G8,"-",""))>=3, "Receipt: From x" & RIGHT(MID(G8, FIND("|", SUBSTITUTE(G8, "-", "|", 3)) + 1, LEN(G8)), 4) & " towards " & IF(ISBLANK(U8), L8, U8) & IF(OR(L8="Cancellation", L8="Collection"), " Apt No " & T8, "") & " (Ref: " & H8 & ") (Type: " & P8 & ") (BU: " & L8 & ") (Head: " & M8 & ")" & IF(ISBLANK(T8), "", " (Apt#: " & T8 & ")"), "Receipt: Against " & IF(ISBLANK(U8), L8, U8) & IF(OR(L8="Cancellation", L8="Collection"), " Apt No " & T8, "") & " (Ref: " & H8 & ") (Type: " & P8 & ") (BU: " & L8 & ") (Head: " & M8 & ")" & IF(ISBLANK(T8), "", " (Apt#: " & T8 & ")"))), IF(LEN(G8)-LEN(SUBSTITUTE(G8,"-",""))>=3, "Payment: To x" & RIGHT(MID(G8, FIND("|", SUBSTITUTE(G8, "-", "|", 3)) + 1, LEN(G8)), 4) & " for " & IF(ISBLANK(U8), L8, U8) & " (Ref: " & H8 & ") (Type: " & P8 & ") (BU: " & L8 & ") (Head: " & M8 & ")" & IF(ISBLANK(T8), "", " (Apt#: " & T8 & ")"), "Payment: Disbursement for " & IF(ISBLANK(U8), "", IF(ISBLANK(U8), "", U8) & " ") & "(Ref: " & H8 & ") (Type: " & P8 & ") (BU: " & L8 & ") (Head: " & M8 & ")" & IF(ISBLANK(T8), "", " (Apt#: " & T8 & ")"))))) -> Receipt: For (Apt#: P-071) (Ref: YBP6228654732943) (IMPS: MRIGANKACHAKRABORTY/XXX7113/RRN:622810783912/AXIS BANK) (Type: Customer Collection) (BU: Casa Romana) | Y8: 129079.78 | Z8: =IFERROR(ROUND(Y8-K8,2),"") -> 1.78
A9: 228 | B9: =IFERROR("Q"&(INT(MOD(C9-4,12)/3)+1),"") -> Q2 | C9: =IFERROR(MONTH(DATEVALUE(D9)),"") -> 8 | D9: 12-Aug-2026 | E9: 12-Aug-2026 | G9: YIB-TPT-DWARKADHIS PROJECTS PVT LT D-INTERNAL-045563400002477 | I9: 45000 | K9: =K10+J9-I9 -> 29078 | L9: Casa Romana | M9: Internal | O9: Entry | P9: Master to Free | Q9: Internal transfer | W9: =TRIM(IF(M9="Internal", IF(ISBLANK(G9), IF(LEN(G9)-LEN(SUBSTITUTE(G9,"-",""))>=3, "Fund Transfer: From x" & RIGHT(MID(G9, FIND("|", SUBSTITUTE(G9, "-", "|", 3)) + 1, LEN(G9)), 4) & " to YES MASTER 0264 (Ref: " & H9 & ") (Type: " & P9 & ") (BU: " & L9 & ") (Head: " & M9 & ")", "Fund Transfer: To YES MASTER 0264 (Ref: " & H9 & ") (Type: " & P9 & ") (BU: " & L9 & ") (Head: " & M9 & ")"), IF(LEN(G9)-LEN(SUBSTITUTE(G9,"-",""))>=3, "Fund Transfer: From YES MASTER 0264 to x" & RIGHT(MID(G9, FIND("|", SUBSTITUTE(G9, "-", "|", 3)) + 1, LEN(G9)), 4) & " (Ref: " & H9 & ") (Type: " & P9 & ") (BU: " & L9 & ") (Head: " & M9 & ")", "Fund Transfer: From YES MASTER 0264 (Ref: " & H9 & ") (Type: " & P9 & ") (BU: " & L9 & ") (Head: " & M9 & ")")), IF(NOT(ISBLANK(J9)), IF(P9="Customer Collection", "Receipt: For " & IF(ISBLANK(T9), "", "(Apt#: " & T9 & ") ") & "(Ref: " & H9 & ") (" & IF(ISNUMBER(SEARCH("NEFT",G9)), "NEFT:", IF(ISNUMBER(SEARCH("RTGS",G9)), "RTGS:", IF(ISNUMBER(SEARCH("IMPS",G9)), "IMPS:", ""))) & " " & IF(ISNUMBER(SEARCH("SOHNA ROAD", G9)), "", IFERROR(MID(G9, FIND("-", G9, FIND("-", G9) + 1) + 1, LEN(G9)), SUBSTITUTE(SUBSTITUTE(SUBSTITUTE(G9, "IMPS/", ""), "NEFT/", ""), "RTGS/", ""))) & ") (Type: " & P9 & ") (BU: " & L9 & ")", IF(LEN(G9)-LEN(SUBSTITUTE(G9,"-",""))>=3, "Receipt: From x" & RIGHT(MID(G9, FIND("|", SUBSTITUTE(G9, "-", "|", 3)) + 1, LEN(G9)), 4) & " towards " & IF(ISBLANK(U9), L9, U9) & IF(OR(L9="Cancellation", L9="Collection"), " Apt No " & T9, "") & " (Ref: " & H9 & ") (Type: " & P9 & ") (BU: " & L9 & ") (Head: " & M9 & ")" & IF(ISBLANK(T9), "", " (Apt#: " & T9 & ")"), "Receipt: Against " & IF(ISBLANK(U9), L9, U9) & IF(OR(L9="Cancellation", L9="Collection"), " Apt No " & T9, "") & " (Ref: " & H9 & ") (Type: " & P9 & ") (BU: " & L9 & ") (Head: " & M9 & ")" & IF(ISBLANK(T9), "", " (Apt#: " & T9 & ")"))), IF(LEN(G9)-LEN(SUBSTITUTE(G9,"-",""))>=3, "Payment: To x" & RIGHT(MID(G9, FIND("|", SUBSTITUTE(G9, "-", "|", 3)) + 1, LEN(G9)), 4) & " for " & IF(ISBLANK(U9), L9, U9) & " (Ref: " & H9 & ") (Type: " & P9 & ") (BU: " & L9 & ") (Head: " & M9 & ")" & IF(ISBLANK(T9), "", " (Apt#: " & T9 & ")"), "Payment: Disbursement for " & IF(ISBLANK(U9), "", IF(ISBLANK(U9), "", U9) & " ") & "(Ref: " & H9 & ") (Type: " & P9 & ") (BU: " & L9 & ") (Head: " & M9 & ")" & IF(ISBLANK(T9), "", " (Apt#: " & T9 & ")"))))) -> Fund Transfer: From YES MASTER 0264 to x2477 (Ref: ) (Type: Master to Free) (BU: Casa Romana) (Head: Internal) | Y9: 29079.78 | Z9: =IFERROR(ROUND(Y9-K9,2),"") -> 1.78
A10: 227 | B10: =IFERROR("Q"&(INT(MOD(C10-4,12)/3)+1),"") -> Q2 | C10: =IFERROR(MONTH(DATEVALUE(D10)),"") -> 8 | D10: 12-Aug-2026 | E10: 12-Aug-2026 | G10: YIB-TPT-DWARKADHIS PROJECTS PRIVATE LIMITED-INTERNAL-0455632 00000377 | I10: 105000 | K10: =K11+J10-I10 -> 74078 | L10: Casa Romana | M10: Internal | O10: Entry | P10: Master 2 RERA | Q10: Internal transfer | W10: =TRIM(IF(M10="Internal", IF(ISBLANK(G10), IF(LEN(G10)-LEN(SUBSTITUTE(G10,"-",""))>=3, "Fund Transfer: From x" & RIGHT(MID(G10, FIND("|", SUBSTITUTE(G10, "-", "|", 3)) + 1, LEN(G10)), 4) & " to YES MASTER 0264 (Ref: " & H10 & ") (Type: " & P10 & ") (BU: " & L10 & ") (Head: " & M10 & ")", "Fund Transfer: To YES MASTER 0264 (Ref: " & H10 & ") (Type: " & P10 & ") (BU: " & L10 & ") (Head: " & M10 & ")"), IF(LEN(G10)-LEN(SUBSTITUTE(G10,"-",""))>=3, "Fund Transfer: From YES MASTER 0264 to x" & RIGHT(MID(G10, FIND("|", SUBSTITUTE(G10, "-", "|", 3)) + 1, LEN(G10)), 4) & " (Ref: " & H10 & ") (Type: " & P10 & ") (BU: " & L10 & ") (Head: " & M10 & ")", "Fund Transfer: From YES MASTER 0264 (Ref: " & H10 & ") (Type: " & P10 & ") (BU: " & L10 & ") (Head: " & M10 & ")")), IF(NOT(ISBLANK(J10)), IF(P10="Customer Collection", "Receipt: For " & IF(ISBLANK(T10), "", "(Apt#: " & T10 & ") ") & "(Ref: " & H10 & ") (" & IF(ISNUMBER(SEARCH("NEFT",G10)), "NEFT:", IF(ISNUMBER(SEARCH("RTGS",G10)), "RTGS:", IF(ISNUMBER(SEARCH("IMPS",G10)), "IMPS:", ""))) & " " & IF(ISNUMBER(SEARCH("SOHNA ROAD", G10)), "", IFERROR(MID(G10, FIND("-", G10, FIND("-", G10) + 1) + 1, LEN(G10)), SUBSTITUTE(SUBSTITUTE(SUBSTITUTE(G10, "IMPS/", ""), "NEFT/", ""), "RTGS/", ""))) & ") (Type: " & P10 & ") (BU: " & L10 & ")", IF(LEN(G10)-LEN(SUBSTITUTE(G10,"-",""))>=3, "Receipt: From x" & RIGHT(MID(G10, FIND("|", SUBSTITUTE(G10, "-", "|", 3)) + 1, LEN(G10)), 4) & " towards " & IF(ISBLANK(U10), L10, U10) & IF(OR(L10="Cancellation", L10="Collection"), " Apt No " & T10, "") & " (Ref: " & H10 & ") (Type: " & P10 & ") (BU: " & L10 & ") (Head: " & M10 & ")" & IF(ISBLANK(T10), "", " (Apt#: " & T10 & ")"), "Receipt: Against " & IF(ISBLANK(U10), L10, U10) & IF(OR(L10="Cancellation", L10="Collection"), " Apt No " & T10, "") & " (Ref: " & H10 & ") (Type: " & P10 & ") (BU: " & L10 & ") (Head: " & M10 & ")" & IF(ISBLANK(T10), "", " (Apt#: " & T10 & ")"))), IF(LEN(G10)-LEN(SUBSTITUTE(G10,"-",""))>=3, "Payment: To x" & RIGHT(MID(G10, FIND("|", SUBSTITUTE(G10, "-", "|", 3)) + 1, LEN(G10)), 4) & " for " & IF(ISBLANK(U10), L10, U10) & " (Ref: " & H10 & ") (Type: " & P10 & ") (BU: " & L10 & ") (Head: " & M10 & ")" & IF(ISBLANK(T10), "", " (Apt#: " & T10 & ")"), "Payment: Disbursement for " & IF(ISBLANK(U10), "", IF(ISBLANK(U10), "", U10) & " ") & "(Ref: " & H10 & ") (Type: " & P10 & ") (BU: " & L10 & ") (Head: " & M10 & ")" & IF(ISBLANK(T10), "", " (Apt#: " & T10 & ")"))))) -> Fund Transfer: From YES MASTER 0264 to x0377 (Ref: ) (Type: Master 2 RERA) (BU: Casa Romana) (Head: Internal) | Y10: 74079.78 | Z10: =IFERROR(ROUND(Y10-K10,2),"") -> 1.78
A11: 226 | B11: =IFERROR("Q"&(INT(MOD(#REF!-4,12)/3)+1),"") | C11: =IFERROR(MONTH(DATEVALUE(D11)),"") -> 8 | D11: 11-Aug-2026 | E11: 11-Aug-2026 | G11: NEFT CR-HDFC0000240- AMIT JAIN-LEKH RAJ BAJAJ-HDFCH01188134343 | H11: YES0N6223910853400 | J11: 50000 | K11: =K12+J11-F11 -> 179078 | L11: Casa Romana | M11: Collection | O11: Entry | P11: Customer Collection | Q11: Credit- no effect | T11: M-105 | V11: On Account | W11: =TRIM(IF(M11="Internal", IF(ISBLANK(G11), IF(LEN(G11)-LEN(SUBSTITUTE(G11,"-",""))>=3, "Fund Transfer: From x" & RIGHT(MID(G11, FIND("|", SUBSTITUTE(G11, "-", "|", 3)) + 1, LEN(G11)), 4) & " to YES MASTER 0264 (Ref: " & H11 & ") (Type: " & P11 & ") (BU: " & L11 & ") (Head: " & M11 & ")", "Fund Transfer: To YES MASTER 0264 (Ref: " & H11 & ") (Type: " & P11 & ") (BU: " & L11 & ") (Head: " & M11 & ")"), IF(LEN(G11)-LEN(SUBSTITUTE(G11,"-",""))>=3, "Fund Transfer: From YES MASTER 0264 to x" & RIGHT(MID(G11, FIND("|", SUBSTITUTE(G11, "-", "|", 3)) + 1, LEN(G11)), 4) & " (Ref: " & H11 & ") (Type: " & P11 & ") (BU: " & L11 & ") (Head: " & M11 & ")", "Fund Transfer: From YES MASTER 0264 (Ref: " & H11 & ") (Type: " & P11 & ") (BU: " & L11 & ") (Head: " & M11 & ")")), IF(NOT(ISBLANK(J11)), IF(P11="Customer Collection", "Receipt: For " & IF(ISBLANK(T11), "", "(Apt#: " & T11 & ") ") & "(Ref: " & H11 & ") (" & IF(ISNUMBER(SEARCH("NEFT",G11)), "NEFT:", IF(ISNUMBER(SEARCH("RTGS",G11)), "RTGS:", IF(ISNUMBER(SEARCH("IMPS",G11)), "IMPS:", ""))) & " " & IF(ISNUMBER(SEARCH("SOHNA ROAD", G11)), "", IFERROR(MID(G11, FIND("-", G11, FIND("-", G11) + 1) + 1, LEN(G11)), SUBSTITUTE(SUBSTITUTE(SUBSTITUTE(G11, "IMPS/", ""), "NEFT/", ""), "RTGS/", ""))) & ") (Type: " & P11 & ") (BU: " & L11 & ")", IF(LEN(G11)-LEN(SUBSTITUTE(G11,"-",""))>=3, "Receipt: From x" & RIGHT(MID(G11, FIND("|", SUBSTITUTE(G11, "-", "|", 3)) + 1, LEN(G11)), 4) & " towards " & IF(ISBLANK(U11), L11, U11) & IF(OR(L11="Cancellation", L11="Collection"), " Apt No " & T11, "") & " (Ref: " & H11 & ") (Type: " & P11 & ") (BU: " & L11 & ") (Head: " & M11 & ")" & IF(ISBLANK(T11), "", " (Apt#: " & T11 & ")"), "Receipt: Against " & IF(ISBLANK(U11), L11, U11) & IF(OR(L11="Cancellation", L11="Collection"), " Apt No " & T11, "") & " (Ref: " & H11 & ") (Type: " & P11 & ") (BU: " & L11 & ") (Head: " & M11 & ")" & IF(ISBLANK(T11), "", " (Apt#: " & T11 & ")"))), IF(LEN(G11)-LEN(SUBSTITUTE(G11,"-",""))>=3, "Payment: To x" & RIGHT(MID(G11, FIND("|", SUBSTITUTE(G11, "-", "|", 3)) + 1, LEN(G11)), 4) & " for " & IF(ISBLANK(U11), L11, U11) & " (Ref: " & H11 & ") (Type: " & P11 & ") (BU: " & L11 & ") (Head: " & M11 & ")" & IF(ISBLANK(T11), "", " (Apt#: " & T11 & ")"), "Payment: Disbursement for " & IF(ISBLANK(U11), "", IF(ISBLANK(U11), "", U11) & " ") & "(Ref: " & H11 & ") (Type: " & P11 & ") (BU: " & L11 & ") (Head: " & M11 & ")" & IF(ISBLANK(T11), "", " (Apt#: " & T11 & ")"))))) -> Receipt: For (Apt#: M-105) (Ref: YES0N6223910853400) (NEFT: AMIT JAIN-LEKH RAJ BAJAJ-HDFCH01188134343) (Type: Customer Collection) (BU: Casa Romana) | X11: 0.01 | Y11: 179079.78 | Z11: =IFERROR(ROUND(Y11-K11,2),"") -> 1.78
A12: 225 | B12: =IFERROR("Q"&(INT(MOD(C12-4,12)/3)+1),"") -> Q2 | C12: =IFERROR(MONTH(DATEVALUE(D12)),"") -> 8 | D12: 10-Aug-2026 | E12: 10-Aug-2026 | G12: NEFT CR-KVBL0002101-RAHULENT ERPRISES-DWARKADHIS PROJECTS PRIVA-KVBLH00267884483 | J12: 100000 | K12: =K13+J12-I12 -> 129078 | L12: Casa Romana | M12: Collection | O12: Entry | P12: Customer Collection | Q12: Credit- no effect | T12: U-013 | V12: On Account | W12: =TRIM(IF(M12="Internal", IF(ISBLANK(G12), IF(LEN(G12)-LEN(SUBSTITUTE(G12,"-",""))>=3, "Fund Transfer: From x" & RIGHT(MID(G12, FIND("|", SUBSTITUTE(G12, "-", "|", 3)) + 1, LEN(G12)), 4) & " to YES MASTER 0264 (Ref: " & H12 & ") (Type: " & P12 & ") (BU: " & L12 & ") (Head: " & M12 & ")", "Fund Transfer: To YES MASTER 0264 (Ref: " & H12 & ") (Type: " & P12 & ") (BU: " & L12 & ") (Head: " & M12 & ")"), IF(LEN(G12)-LEN(SUBSTITUTE(G12,"-",""))>=3, "Fund Transfer: From YES MASTER 0264 to x" & RIGHT(MID(G12, FIND("|", SUBSTITUTE(G12, "-", "|", 3)) + 1, LEN(G12)), 4) & " (Ref: " & H12 & ") (Type: " & P12 & ") (BU: " & L12 & ") (Head: " & M12 & ")", "Fund Transfer: From YES MASTER 0264 (Ref: " & H12 & ") (Type: " & P12 & ") (BU: " & L12 & ") (Head: " & M12 & ")")), IF(NOT(ISBLANK(J12)), IF(P12="Customer Collection", "Receipt: For " & IF(ISBLANK(T12), "", "(Apt#: " & T12 & ") ") & "(Ref: " & H12 & ") (" & IF(ISNUMBER(SEARCH("NEFT",G12)), "NEFT:", IF(ISNUMBER(SEARCH("RTGS",G12)), "RTGS:", IF(ISNUMBER(SEARCH("IMPS",G12)), "IMPS:", ""))) & " " & IF(ISNUMBER(SEARCH("SOHNA ROAD", G12)), "", IFERROR(MID(G12, FIND("-", G12, FIND("-", G12) + 1) + 1, LEN(G12)), SUBSTITUTE(SUBSTITUTE(SUBSTITUTE(G12, "IMPS/", ""), "NEFT/", ""), "RTGS/", ""))) & ") (Type: " & P12 & ") (BU: " & L12 & ")", IF(LEN(G12)-LEN(SUBSTITUTE(G12,"-",""))>=3, "Receipt: From x" & RIGHT(MID(G12, FIND("|", SUBSTITUTE(G12, "-", "|", 3)) + 1, LEN(G12)), 4) & " towards " & IF(ISBLANK(U12), L12, U12) & IF(OR(L12="Cancellation", L12="Collection"), " Apt No " & T12, "") & " (Ref: " & H12 & ") (Type: " & P12 & ") (BU: " & L12 & ") (Head: " & M12 & ")" & IF(ISBLANK(T12), "", " (Apt#: " & T12 & ")"), "Receipt: Against " & IF(ISBLANK(U12), L12, U12) & IF(OR(L12="Cancellation", L12="Collection"), " Apt No " & T12, "") & " (Ref: " & H12 & ") (Type: " & P12 & ") (BU: " & L12 & ") (Head: " & M12 & ")" & IF(ISBLANK(T12), "", " (Apt#: " & T12 & ")"))), IF(LEN(G12)-LEN(SUBSTITUTE(G12,"-",""))>=3, "Payment: To x" & RIGHT(MID(G12, FIND("|", SUBSTITUTE(G12, "-", "|", 3)) + 1, LEN(G12)), 4) & " for " & IF(ISBLANK(U12), L12, U12) & " (Ref: " & H12 & ") (Type: " & P12 & ") (BU: " & L12 & ") (Head: " & M12 & ")" & IF(ISBLANK(T12), "", " (Apt#: " & T12 & ")"), "Payment: Disbursement for " & IF(ISBLANK(U12), "", IF(ISBLANK(U12), "", U12) & " ") & "(Ref: " & H12 & ") (Type: " & P12 & ") (BU: " & L12 & ") (Head: " & M12 & ")" & IF(ISBLANK(T12), "", " (Apt#: " & T12 & ")"))))) -> Receipt: For (Apt#: U-013) (Ref: ) (NEFT: RAHULENT ERPRISES-DWARKADHIS PROJECTS PRIVA-KVBLH00267884483) (Type: Customer Collection) (BU: Casa Romana) | X12: 0.05 | Y12: 129079.78 | Z12: =IFERROR(ROUND(Y12-K12,2),"") -> 1.78
A13: 224 | B13: =IFERROR("Q"&(INT(MOD(C13-4,12)/3)+1),"") -> Q2 | C13: =IFERROR(MONTH(DATEVALUE(D13)),"") -> 8 | D13: 06-Aug-2026 | E13: 06-Aug-2026 | G13: YIB-TPT-DWARKADHIS PROJECTS PRIVATE LIMITED-INTERNAL-0455632 00000377 | I13: 198629 | K13: =K14+J13-I13 -> 29078 | L13: Casa Romana | M13: Internal | O13: Entry | P13: Master 2 RERA | Q13: Internal transfer | W13: =TRIM(IF(M13="Internal", IF(ISBLANK(G13), IF(LEN(G13)-LEN(SUBSTITUTE(G13,"-",""))>=3, "Fund Transfer: From x" & RIGHT(MID(G13, FIND("|", SUBSTITUTE(G13, "-", "|", 3)) + 1, LEN(G13)), 4) & " to YES MASTER 0264 (Ref: " & H13 & ") (Type: " & P13 & ") (BU: " & L13 & ") (Head: " & M13 & ")", "Fund Transfer: To YES MASTER 0264 (Ref: " & H13 & ") (Type: " & P13 & ") (BU: " & L13 & ") (Head: " & M13 & ")"), IF(LEN(G13)-LEN(SUBSTITUTE(G13,"-",""))>=3, "Fund Transfer: From YES MASTER 0264 to x" & RIGHT(MID(G13, FIND("|", SUBSTITUTE(G13, "-", "|", 3)) + 1, LEN(G13)), 4) & " (Ref: " & H13 & ") (Type: " & P13 & ") (BU: " & L13 & ") (Head: " & M13 & ")", "Fund Transfer: From YES MASTER 0264 (Ref: " & H13 & ") (Type: " & P13 & ") (BU: " & L13 & ") (Head: " & M13 & ")")), IF(NOT(ISBLANK(J13)), IF(P13="Customer Collection", "Receipt: For " & IF(ISBLANK(T13), "", "(Apt#: " & T13 & ") ") & "(Ref: " & H13 & ") (" & IF(ISNUMBER(SEARCH("NEFT",G13)), "NEFT:", IF(ISNUMBER(SEARCH("RTGS",G13)), "RTGS:", IF(ISNUMBER(SEARCH("IMPS",G13)), "IMPS:", ""))) & " " & IF(ISNUMBER(SEARCH("SOHNA ROAD", G13)), "", IFERROR(MID(G13, FIND("-", G13, FIND("-", G13) + 1) + 1, LEN(G13)), SUBSTITUTE(SUBSTITUTE(SUBSTITUTE(G13, "IMPS/", ""), "NEFT/", ""), "RTGS/", ""))) & ") (Type: " & P13 & ") (BU: " & L13 & ")", IF(LEN(G13)-LEN(SUBSTITUTE(G13,"-",""))>=3, "Receipt: From x" & RIGHT(MID(G13, FIND("|", SUBSTITUTE(G13, "-", "|", 3)) + 1, LEN(G13)), 4) & " towards " & IF(ISBLANK(U13), L13, U13) & IF(OR(L13="Cancellation", L13="Collection"), " Apt No " & T13, "") & " (Ref: " & H13 & ") (Type: " & P13 & ") (BU: " & L13 & ") (Head: " & M13 & ")" & IF(ISBLANK(T13), "", " (Apt#: " & T13 & ")"), "Receipt: Against " & IF(ISBLANK(U13), L13, U13) & IF(OR(L13="Cancellation", L13="Collection"), " Apt No " & T13, "") & " (Ref: " & H13 & ") (Type: " & P13 & ") (BU: " & L13 & ") (Head: " & M13 & ")" & IF(ISBLANK(T13), "", " (Apt#: " & T13 & ")"))), IF(LEN(G13)-LEN(SUBSTITUTE(G13,"-",""))>=3, "Payment: To x" & RIGHT(MID(G13, FIND("|", SUBSTITUTE(G13, "-", "|", 3)) + 1, LEN(G13)), 4) & " for " & IF(ISBLANK(U13), L13, U13) & " (Ref: " & H13 & ") (Type: " & P13 & ") (BU: " & L13 & ") (Head: " & M13 & ")" & IF(ISBLANK(T13), "", " (Apt#: " & T13 & ")"), "Payment: Disbursement for " & IF(ISBLANK(U13), "", IF(ISBLANK(U13), "", U13) & " ") & "(Ref: " & H13 & ") (Type: " & P13 & ") (BU: " & L13 & ") (Head: " & M13 & ")" & IF(ISBLANK(T13), "", " (Apt#: " & T13 & ")"))))) -> Fund Transfer: From YES MASTER 0264 to x0377 (Ref: ) (Type: Master 2 RERA) (BU: Casa Romana) (Head: Internal) | Y13: 29079.78 | Z13: =Y13-K13 -> 1.78
A14: 223 | B14: =IFERROR("Q"&(INT(MOD(C14-4,12)/3)+1),"") -> Q2 | C14: =IFERROR(MONTH(DATEVALUE(D14)),"") -> 8 | D14: 06-Aug-2026 | E14: 06-Aug-2026 | G14: YIB-TPT-DWARKADHIS PROJECTS PVT LT D-INTERNAL-045563400002477 | I14: 85127 | K14: =K15+J14-I14 -> 227707 | L14: Casa Romana | M14: Internal | O14: Entry | P14: Master to Free | Q14: Internal transfer | W14: =TRIM(IF(M14="Internal", IF(ISBLANK(G14), IF(LEN(G14)-LEN(SUBSTITUTE(G14,"-",""))>=3, "Fund Transfer: From x" & RIGHT(MID(G14, FIND("|", SUBSTITUTE(G14, "-", "|", 3)) + 1, LEN(G14)), 4) & " to YES MASTER 0264 (Ref: " & H14 & ") (Type: " & P14 & ") (BU: " & L14 & ") (Head: " & M14 & ")", "Fund Transfer: To YES MASTER 0264 (Ref: " & H14 & ") (Type: " & P14 & ") (BU: " & L14 & ") (Head: " & M14 & ")"), IF(LEN(G14)-LEN(SUBSTITUTE(G14,"-",""))>=3, "Fund Transfer: From YES MASTER 0264 to x" & RIGHT(MID(G14, FIND("|", SUBSTITUTE(G14, "-", "|", 3)) + 1, LEN(G14)), 4) & " (Ref: " & H14 & ") (Type: " & P14 & ") (BU: " & L14 & ") (Head: " & M14 & ")", "Fund Transfer: From YES MASTER 0264 (Ref: " & H14 & ") (Type: " & P14 & ") (BU: " & L14 & ") (Head: " & M14 & ")")), IF(NOT(ISBLANK(J14)), IF(P14="Customer Collection", "Receipt: For " & IF(ISBLANK(T14), "", "(Apt#: " & T14 & ") ") & "(Ref: " & H14 & ") (" & IF(ISNUMBER(SEARCH("NEFT",G14)), "NEFT:", IF(ISNUMBER(SEARCH("RTGS",G14)), "RTGS:", IF(ISNUMBER(SEARCH("IMPS",G14)), "IMPS:", ""))) & " " & IF(ISNUMBER(SEARCH("SOHNA ROAD", G14)), "", IFERROR(MID(G14, FIND("-", G14, FIND("-", G14) + 1) + 1, LEN(G14)), SUBSTITUTE(SUBSTITUTE(SUBSTITUTE(G14, "IMPS/", ""), "NEFT/", ""), "RTGS/", ""))) & ") (Type: " & P14 & ") (BU: " & L14 & ")", IF(LEN(G14)-LEN(SUBSTITUTE(G14,"-",""))>=3, "Receipt: From x" & RIGHT(MID(G14, FIND("|", SUBSTITUTE(G14, "-", "|", 3)) + 1, LEN(G14)), 4) & " towards " & IF(ISBLANK(U14), L14, U14) & IF(OR(L14="Cancellation", L14="Collection"), " Apt No " & T14, "") & " (Ref: " & H14 & ") (Type: " & P14 & ") (BU: " & L14 & ") (Head: " & M14 & ")" & IF(ISBLANK(T14), "", " (Apt#: " & T14 & ")"), "Receipt: Against " & IF(ISBLANK(U14), L14, U14) & IF(OR(L14="Cancellation", L14="Collection"), " Apt No " & T14, "") & " (Ref: " & H14 & ") (Type: " & P14 & ") (BU: " & L14 & ") (Head: " & M14 & ")" & IF(ISBLANK(T14), "", " (Apt#: " & T14 & ")"))), IF(LEN(G14)-LEN(SUBSTITUTE(G14,"-",""))>=3, "Payment: To x" & RIGHT(MID(G14, FIND("|", SUBSTITUTE(G14, "-", "|", 3)) + 1, LEN(G14)), 4) & " for " & IF(ISBLANK(U14), L14, U14) & " (Ref: " & H14 & ") (Type: " & P14 & ") (BU: " & L14 & ") (Head: " & M14 & ")" & IF(ISBLANK(T14), "", " (Apt#: " & T14 & ")"), "Payment: Disbursement for " & IF(ISBLANK(U14), "", IF(ISBLANK(U14), "", U14) & " ") & "(Ref: " & H14 & ") (Type: " & P14 & ") (BU: " & L14 & ") (Head: " & M14 & ")" & IF(ISBLANK(T14), "", " (Apt#: " & T14 & ")"))))) -> Fund Transfer: From YES MASTER 0264 to x2477 (Ref: ) (Type: Master to Free) (BU: Casa Romana) (Head: Internal) | Y14: 227708.78 | Z14: =Y14-K14 -> 1.78
A15: 222 | B15: =IFERROR("Q"&(INT(MOD(C15-4,12)/3)+1),"") -> Q2 | C15: =IFERROR(MONTH(DATEVALUE(D15)),"") -> 8 | D15: 06-Aug-2026 | E15: 06-Aug-2026 | G15: NET-TPT-ASHISH SHUKLA-071691900001571 | J15: 15000 | K15: =K16+J15-I15 -> 312834 | L15: Casa Romana | M15: Collection | O15: Entry | P15: Customer Collection | Q15: Credit- no effect | T15: T-052 | V15: On Account | W15: =TRIM(IF(M15="Internal", IF(ISBLANK(G15), IF(LEN(G15)-LEN(SUBSTITUTE(G15,"-",""))>=3, "Fund Transfer: From x" & RIGHT(MID(G15, FIND("|", SUBSTITUTE(G15, "-", "|", 3)) + 1, LEN(G15)), 4) & " to YES MASTER 0264 (Ref: " & H15 & ") (Type: " & P15 & ") (BU: " & L15 & ") (Head: " & M15 & ")", "Fund Transfer: To YES MASTER 0264 (Ref: " & H15 & ") (Type: " & P15 & ") (BU: " & L15 & ") (Head: " & M15 & ")"), IF(LEN(G15)-LEN(SUBSTITUTE(G15,"-",""))>=3, "Fund Transfer: From YES MASTER 0264 to x" & RIGHT(MID(G15, FIND("|", SUBSTITUTE(G15, "-", "|", 3)) + 1, LEN(G15)), 4) & " (Ref: " & H15 & ") (Type: " & P15 & ") (BU: " & L15 & ") (Head: " & M15 & ")", "Fund Transfer: From YES MASTER 0264 (Ref: " & H15 & ") (Type: " & P15 & ") (BU: " & L15 & ") (Head: " & M15 & ")")), IF(NOT(ISBLANK(J15)), IF(P15="Customer Collection", "Receipt: For " & IF(ISBLANK(T15), "", "(Apt#: " & T15 & ") ") & "(Ref: " & H15 & ") (" & IF(ISNUMBER(SEARCH("NEFT",G15)), "NEFT:", IF(ISNUMBER(SEARCH("RTGS",G15)), "RTGS:", IF(ISNUMBER(SEARCH("IMPS",G15)), "IMPS:", ""))) & " " & IF(ISNUMBER(SEARCH("SOHNA ROAD", G15)), "", IFERROR(MID(G15, FIND("-", G15, FIND("-", G15) + 1) + 1, LEN(G15)), SUBSTITUTE(SUBSTITUTE(SUBSTITUTE(G15, "IMPS/", ""), "NEFT/", ""), "RTGS/", ""))) & ") (Type: " & P15 & ") (BU: " & L15 & ")", IF(LEN(G15)-LEN(SUBSTITUTE(G15,"-",""))>=3, "Receipt: From x" & RIGHT(MID(G15, FIND("|", SUBSTITUTE(G15, "-", "|", 3)) + 1, LEN(G15)), 4) & " towards " & IF(ISBLANK(U15), L15, U15) & IF(OR(L15="Cancellation", L15="Collection"), " Apt No " & T15, "") & " (Ref: " & H15 & ") (Type: " & P15 & ") (BU: " & L15 & ") (Head: " & M15 & ")" & IF(ISBLANK(T15), "", " (Apt#: " & T15 & ")"), "Receipt: Against " & IF(ISBLANK(U15), L15, U15) & IF(OR(L15="Cancellation", L15="Collection"), " Apt No " & T15, "") & " (Ref: " & H15 & ") (Type: " & P15 & ") (BU: " & L15 & ") (Head: " & M15 & ")" & IF(ISBLANK(T15), "", " (Apt#: " & T15 & ")"))), IF(LEN(G15)-LEN(SUBSTITUTE(G15,"-",""))>=3, "Payment: To x" & RIGHT(MID(G15, FIND("|", SUBSTITUTE(G15, "-", "|", 3)) + 1, LEN(G15)), 4) & " for " & IF(ISBLANK(U15), L15, U15) & " (Ref: " & H15 & ") (Type: " & P15 & ") (BU: " & L15 & ") (Head: " & M15 & ")" & IF(ISBLANK(T15), "", " (Apt#: " & T15 & ")"), "Payment: Disbursement for " & IF(ISBLANK(U15), "", IF(ISBLANK(U15), "", U15) & " ") & "(Ref: " & H15 & ") (Type: " & P15 & ") (BU: " & L15 & ") (Head: " & M15 & ")" & IF(ISBLANK(T15), "", " (Apt#: " & T15 & ")"))))) -> Receipt: For (Apt#: T-052) (Ref: ) ( ASHISH SHUKLA-071691900001571) (Type: Customer Collection) (BU: Casa Romana) | X15: 0.05 | Y15: 312835.78 | Z15: =Y15-K15 -> 1.78
A16: 221 | B16: =IFERROR("Q"&(INT(MOD(C16-4,12)/3)+1),"") -> Q2 | C16: =IFERROR(MONTH(DATEVALUE(D16)),"") -> 8 | D16: 05-Aug-2026 | E16: 05-Aug-2026 | G16: RTGS CR-HDFC0000240-VANDANA KHULLAR-DWARKADHIS PROJECTS PVTL-HDFCR52026080592593517 | J16: 218756 | K16: =K17+J16-I16 -> 297834 | L16: Casa Romana | M16: Collection | O16: Entry | P16: Customer Collection | Q16: Credit- no effect | T16: L-064 | V16: Adjust | W16: =TRIM(IF(M16="Internal", IF(ISBLANK(G16), IF(LEN(G16)-LEN(SUBSTITUTE(G16,"-",""))>=3, "Fund Transfer: From x" & RIGHT(MID(G16, FIND("|", SUBSTITUTE(G16, "-", "|", 3)) + 1, LEN(G16)), 4) & " to YES MASTER 0264 (Ref: " & H16 & ") (Type: " & P16 & ") (BU: " & L16 & ") (Head: " & M16 & ")", "Fund Transfer: To YES MASTER 0264 (Ref: " & H16 & ") (Type: " & P16 & ") (BU: " & L16 & ") (Head: " & M16 & ")"), IF(LEN(G16)-LEN(SUBSTITUTE(G16,"-",""))>=3, "Fund Transfer: From YES MASTER 0264 to x" & RIGHT(MID(G16, FIND("|", SUBSTITUTE(G16, "-", "|", 3)) + 1, LEN(G16)), 4) & " (Ref: " & H16 & ") (Type: " & P16 & ") (BU: " & L16 & ") (Head: " & M16 & ")", "Fund Transfer: From YES MASTER 0264 (Ref: " & H16 & ") (Type: " & P16 & ") (BU: " & L16 & ") (Head: " & M16 & ")")), IF(NOT(ISBLANK(J16)), IF(P16="Customer Collection", "Receipt: For " & IF(ISBLANK(T16), "", "(Apt#: " & T16 & ") ") & "(Ref: " & H16 & ") (" & IF(ISNUMBER(SEARCH("NEFT",G16)), "NEFT:", IF(ISNUMBER(SEARCH("RTGS",G16)), "RTGS:", IF(ISNUMBER(SEARCH("IMPS",G16)), "IMPS:", ""))) & " " & IF(ISNUMBER(SEARCH("SOHNA ROAD", G16)), "", IFERROR(MID(G16, FIND("-", G16, FIND("-", G16) + 1) + 1, LEN(G16)), SUBSTITUTE(SUBSTITUTE(SUBSTITUTE(G16, "IMPS/", ""), "NEFT/", ""), "RTGS/", ""))) & ") (Type: " & P16 & ") (BU: " & L16 & ")", IF(LEN(G16)-LEN(SUBSTITUTE(G16,"-",""))>=3, "Receipt: From x" & RIGHT(MID(G16, FIND("|", SUBSTITUTE(G16, "-", "|", 3)) + 1, LEN(G16)), 4) & " towards " & IF(ISBLANK(U16), L16, U16) & IF(OR(L16="Cancellation", L16="Collection"), " Apt No " & T16, "") & " (Ref: " & H16 & ") (Type: " & P16 & ") (BU: " & L16 & ") (Head: " & M16 & ")" & IF(ISBLANK(T16), "", " (Apt#: " & T16 & ")"), "Receipt: Against " & IF(ISBLANK(U16), L16, U16) & IF(OR(L16="Cancellation", L16="Collection"), " Apt No " & T16, "") & " (Ref: " & H16 & ") (Type: " & P16 & ") (BU: " & L16 & ") (Head: " & M16 & ")" & IF(ISBLANK(T16), "", " (Apt#: " & T16 & ")"))), IF(LEN(G16)-LEN(SUBSTITUTE(G16,"-",""))>=3, "Payment: To x" & RIGHT(MID(G16, FIND("|", SUBSTITUTE(G16, "-", "|", 3)) + 1, LEN(G16)), 4) & " for " & IF(ISBLANK(U16), L16, U16) & " (Ref: " & H16 & ") (Type: " & P16 & ") (BU: " & L16 & ") (Head: " & M16 & ")" & IF(ISBLANK(T16), "", " (Apt#: " & T16 & ")"), "Payment: Disbursement for " & IF(ISBLANK(U16), "", IF(ISBLANK(U16), "", U16) & " ") & "(Ref: " & H16 & ") (Type: " & P16 & ") (BU: " & L16 & ") (Head: " & M16 & ")" & IF(ISBLANK(T16), "", " (Apt#: " & T16 & ")"))))) -> Receipt: For (Apt#: L-064) (Ref: ) (RTGS: VANDANA KHULLAR-DWARKADHIS PROJECTS PVTL-HDFCR52026080592593517) (Type: Customer Collection) (BU: Casa Romana) | Y16: 297835.78 | Z16: =Y16-K16 -> 1.78
A17: 220 | B17: =IFERROR("Q"&(INT(MOD(C17-4,12)/3)+1),"") -> Q2 | C17: =IFERROR(MONTH(DATEVALUE(D17)),"") -> 8 | D17: 05-Aug-2026 | E17: 05-Aug-2026 | G17: NEFT CR-HDFC0000001-CHETAN A HUJA-DWARKADHIS PROJECTS PRIVA-HDFCH01173383398 | J17: 50000 | K17: =K18+J17-I17 -> 79078 | L17: Casa Romana | M17: Collection | O17: Entry | P17: Customer Collection | Q17: Credit- no effect | T17: U-062 | V17: Adjust | W17: =TRIM(IF(M17="Internal", IF(ISBLANK(G17), IF(LEN(G17)-LEN(SUBSTITUTE(G17,"-",""))>=3, "Fund Transfer: From x" & RIGHT(MID(G17, FIND("|", SUBSTITUTE(G17, "-", "|", 3)) + 1, LEN(G17)), 4) & " to YES MASTER 0264 (Ref: " & H17 & ") (Type: " & P17 & ") (BU: " & L17 & ") (Head: " & M17 & ")", "Fund Transfer: To YES MASTER 0264 (Ref: " & H17 & ") (Type: " & P17 & ") (BU: " & L17 & ") (Head: " & M17 & ")"), IF(LEN(G17)-LEN(SUBSTITUTE(G17,"-",""))>=3, "Fund Transfer: From YES MASTER 0264 to x" & RIGHT(MID(G17, FIND("|", SUBSTITUTE(G17, "-", "|", 3)) + 1, LEN(G17)), 4) & " (Ref: " & H17 & ") (Type: " & P17 & ") (BU: " & L17 & ") (Head: " & M17 & ")", "Fund Transfer: From YES MASTER 0264 (Ref: " & H17 & ") (Type: " & P17 & ") (BU: " & L17 & ") (Head: " & M17 & ")")), IF(NOT(ISBLANK(J17)), IF(P17="Customer Collection", "Receipt: For " & IF(ISBLANK(T17), "", "(Apt#: " & T17 & ") ") & "(Ref: " & H17 & ") (" & IF(ISNUMBER(SEARCH("NEFT",G17)), "NEFT:", IF(ISNUMBER(SEARCH("RTGS",G17)), "RTGS:", IF(ISNUMBER(SEARCH("IMPS",G17)), "IMPS:", ""))) & " " & IF(ISNUMBER(SEARCH("SOHNA ROAD", G17)), "", IFERROR(MID(G17, FIND("-", G17, FIND("-", G17) + 1) + 1, LEN(G17)), SUBSTITUTE(SUBSTITUTE(SUBSTITUTE(G17, "IMPS/", ""), "NEFT/", ""), "RTGS/", ""))) & ") (Type: " & P17 & ") (BU: " & L17 & ")", IF(LEN(G17)-LEN(SUBSTITUTE(G17,"-",""))>=3, "Receipt: From x" & RIGHT(MID(G17, FIND("|", SUBSTITUTE(G17, "-", "|", 3)) + 1, LEN(G17)), 4) & " towards " & IF(ISBLANK(U17), L17, U17) & IF(OR(L17="Cancellation", L17="Collection"), " Apt No " & T17, "") & " (Ref: " & H17 & ") (Type: " & P17 & ") (BU: " & L17 & ") (Head: " & M17 & ")" & IF(ISBLANK(T17), "", " (Apt#: " & T17 & ")"), "Receipt: Against " & IF(ISBLANK(U17), L17, U17) & IF(OR(L17="Cancellation", L17="Collection"), " Apt No " & T17, "") & " (Ref: " & H17 & ") (Type: " & P17 & ") (BU: " & L17 & ") (Head: " & M17 & ")" & IF(ISBLANK(T17), "", " (Apt#: " & T17 & ")"))), IF(LEN(G17)-LEN(SUBSTITUTE(G17,"-",""))>=3, "Payment: To x" & RIGHT(MID(G17, FIND("|", SUBSTITUTE(G17, "-", "|", 3)) + 1, LEN(G17)), 4) & " for " & IF(ISBLANK(U17), L17, U17) & " (Ref: " & H17 & ") (Type: " & P17 & ") (BU: " & L17 & ") (Head: " & M17 & ")" & IF(ISBLANK(T17), "", " (Apt#: " & T17 & ")"), "Payment: Disbursement for " & IF(ISBLANK(U17), "", IF(ISBLANK(U17), "", U17) & " ") & "(Ref: " & H17 & ") (Type: " & P17 & ") (BU: " & L17 & ") (Head: " & M17 & ")" & IF(ISBLANK(T17), "", " (Apt#: " & T17 & ")"))))) -> Receipt: For (Apt#: U-062) (Ref: ) (NEFT: CHETAN A HUJA-DWARKADHIS PROJECTS PRIVA-HDFCH01173383398) (Type: Customer Collection) (BU: Casa Romana) | Y17: 79079.78 | Z17: =Y17-K17 -> 1.78
A18: 219 | B18: =IFERROR("Q"&(INT(MOD(C18-4,12)/3)+1),"") -> Q2 | C18: =IFERROR(MONTH(DATEVALUE(D18)),"") -> 8 | D18: 05-Aug-2026 | E18: 05-Aug-2026 | G18: YIB-TPT-DWARKADHIS PROJECTS PVT LT D-INTERNAL-045563400002477 | I18: 99576 | K18: =K19+J18-I18 -> 29078 | L18: Casa Romana | M18: Internal | O18: Entry | P18: Master to Free | Q18: Internal transfer | W18: =TRIM(IF(M18="Internal", IF(ISBLANK(G18), IF(LEN(G18)-LEN(SUBSTITUTE(G18,"-",""))>=3, "Fund Transfer: From x" & RIGHT(MID(G18, FIND("|", SUBSTITUTE(G18, "-", "|", 3)) + 1, LEN(G18)), 4) & " to YES MASTER 0264 (Ref: " & H18 & ") (Type: " & P18 & ") (BU: " & L18 & ") (Head: " & M18 & ")", "Fund Transfer: To YES MASTER 0264 (Ref: " & H18 & ") (Type: " & P18 & ") (BU: " & L18 & ") (Head: " & M18 & ")"), IF(LEN(G18)-LEN(SUBSTITUTE(G18,"-",""))>=3, "Fund Transfer: From YES MASTER 0264 to x" & RIGHT(MID(G18, FIND("|", SUBSTITUTE(G18, "-", "|", 3)) + 1, LEN(G18)), 4) & " (Ref: " & H18 & ") (Type: " & P18 & ") (BU: " & L18 & ") (Head: " & M18 & ")", "Fund Transfer: From YES MASTER 0264 (Ref: " & H18 & ") (Type: " & P18 & ") (BU: " & L18 & ") (Head: " & M18 & ")")), IF(NOT(ISBLANK(J18)), IF(P18="Customer Collection", "Receipt: For " & IF(ISBLANK(T18), "", "(Apt#: " & T18 & ") ") & "(Ref: " & H18 & ") (" & IF(ISNUMBER(SEARCH("NEFT",G18)), "NEFT:", IF(ISNUMBER(SEARCH("RTGS",G18)), "RTGS:", IF(ISNUMBER(SEARCH("IMPS",G18)), "IMPS:", ""))) & " " & IF(ISNUMBER(SEARCH("SOHNA ROAD", G18)), "", IFERROR(MID(G18, FIND("-", G18, FIND("-", G18) + 1) + 1, LEN(G18)), SUBSTITUTE(SUBSTITUTE(SUBSTITUTE(G18, "IMPS/", ""), "NEFT/", ""), "RTGS/", ""))) & ") (Type: " & P18 & ") (BU: " & L18 & ")", IF(LEN(G18)-LEN(SUBSTITUTE(G18,"-",""))>=3, "Receipt: From x" & RIGHT(MID(G18, FIND("|", SUBSTITUTE(G18, "-", "|", 3)) + 1, LEN(G18)), 4) & " towards " & IF(ISBLANK(U18), L18, U18) & IF(OR(L18="Cancellation", L18="Collection"), " Apt No " & T18, "") & " (Ref: " & H18 & ") (Type: " & P18 & ") (BU: " & L18 & ") (Head: " & M18 & ")" & IF(ISBLANK(T18), "", " (Apt#: " & T18 & ")"), "Receipt: Against " & IF(ISBLANK(U18), L18, U18) & IF(OR(L18="Cancellation", L18="Collection"), " Apt No " & T18, "") & " (Ref: " & H18 & ") (Type: " & P18 & ") (BU: " & L18 & ") (Head: " & M18 & ")" & IF(ISBLANK(T18), "", " (Apt#: " & T18 & ")"))), IF(LEN(G18)-LEN(SUBSTITUTE(G18,"-",""))>=3, "Payment: To x" & RIGHT(MID(G18, FIND("|", SUBSTITUTE(G18, "-", "|", 3)) + 1, LEN(G18)), 4) & " for " & IF(ISBLANK(U18), L18, U18) & " (Ref: " & H18 & ") (Type: " & P18 & ") (BU: " & L18 & ") (Head: " & M18 & ")" & IF(ISBLANK(T18), "", " (Apt#: " & T18 & ")"), "Payment: Disbursement for " & IF(ISBLANK(U18), "", IF(ISBLANK(U18), "", U18) & " ") & "(Ref: " & H18 & ") (Type: " & P18 & ") (BU: " & L18 & ") (Head: " & M18 & ")" & IF(ISBLANK(T18), "", " (Apt#: " & T18 & ")"))))) -> Fund Transfer: From YES MASTER 0264 to x2477 (Ref: ) (Type: Master to Free) (BU: Casa Romana) (Head: Internal) | Y18: 29079.78 | Z18: =Y18-K18 -> 1.78
A19: 218 | B19: =IFERROR("Q"&(INT(MOD(C19-4,12)/3)+1),"") -> Q2 | C19: =IFERROR(MONTH(DATEVALUE(D19)),"") -> 8 | D19: 05-Aug-2026 | E19: 05-Aug-2026 | G19: YIB-TPT-DWARKADHIS PROJECTS PRIVATE LIMITED-INTERNAL-0455632 00000377 | I19: 232344 | K19: =K20+J19-I19 -> 128654 | L19: Casa Romana | M19: Internal | O19: Entry | P19: Master 2 RERA | Q19: Internal transfer | W19: =TRIM(IF(M19="Internal", IF(ISBLANK(G19), IF(LEN(G19)-LEN(SUBSTITUTE(G19,"-",""))>=3, "Fund Transfer: From x" & RIGHT(MID(G19, FIND("|", SUBSTITUTE(G19, "-", "|", 3)) + 1, LEN(G19)), 4) & " to YES MASTER 0264 (Ref: " & H19 & ") (Type: " & P19 & ") (BU: " & L19 & ") (Head: " & M19 & ")", "Fund Transfer: To YES MASTER 0264 (Ref: " & H19 & ") (Type: " & P19 & ") (BU: " & L19 & ") (Head: " & M19 & ")"), IF(LEN(G19)-LEN(SUBSTITUTE(G19,"-",""))>=3, "Fund Transfer: From YES MASTER 0264 to x" & RIGHT(MID(G19, FIND("|", SUBSTITUTE(G19, "-", "|", 3)) + 1, LEN(G19)), 4) & " (Ref: " & H19 & ") (Type: " & P19 & ") (BU: " & L19 & ") (Head: " & M19 & ")", "Fund Transfer: From YES MASTER 0264 (Ref: " & H19 & ") (Type: " & P19 & ") (BU: " & L19 & ") (Head: " & M19 & ")")), IF(NOT(ISBLANK(J19)), IF(P19="Customer Collection", "Receipt: For " & IF(ISBLANK(T19), "", "(Apt#: " & T19 & ") ") & "(Ref: " & H19 & ") (" & IF(ISNUMBER(SEARCH("NEFT",G19)), "NEFT:", IF(ISNUMBER(SEARCH("RTGS",G19)), "RTGS:", IF(ISNUMBER(SEARCH("IMPS",G19)), "IMPS:", ""))) & " " & IF(ISNUMBER(SEARCH("SOHNA ROAD", G19)), "", IFERROR(MID(G19, FIND("-", G19, FIND("-", G19) + 1) + 1, LEN(G19)), SUBSTITUTE(SUBSTITUTE(SUBSTITUTE(G19, "IMPS/", ""), "NEFT/", ""), "RTGS/", ""))) & ") (Type: " & P19 & ") (BU: " & L19 & ")", IF(LEN(G19)-LEN(SUBSTITUTE(G19,"-",""))>=3, "Receipt: From x" & RIGHT(MID(G19, FIND("|", SUBSTITUTE(G19, "-", "|", 3)) + 1, LEN(G19)), 4) & " towards " & IF(ISBLANK(U19), L19, U19) & IF(OR(L19="Cancellation", L19="Collection"), " Apt No " & T19, "") & " (Ref: " & H19 & ") (Type: " & P19 & ") (BU: " & L19 & ") (Head: " & M19 & ")" & IF(ISBLANK(T19), "", " (Apt#: " & T19 & ")"), "Receipt: Against " & IF(ISBLANK(U19), L19, U19) & IF(OR(L19="Cancellation", L19="Collection"), " Apt No " & T19, "") & " (Ref: " & H19 & ") (Type: " & P19 & ") (BU: " & L19 & ") (Head: " & M19 & ")" & IF(ISBLANK(T19), "", " (Apt#: " & T19 & ")"))), IF(LEN(G19)-LEN(SUBSTITUTE(G19,"-",""))>=3, "Payment: To x" & RIGHT(MID(G19, FIND("|", SUBSTITUTE(G19, "-", "|", 3)) + 1, LEN(G19)), 4) & " for " & IF(ISBLANK(U19), L19, U19) & " (Ref: " & H19 & ") (Type: " & P19 & ") (BU: " & L19 & ") (Head: " & M19 & ")" & IF(ISBLANK(T19), "", " (Apt#: " & T19 & ")"), "Payment: Disbursement for " & IF(ISBLANK(U19), "", IF(ISBLANK(U19), "", U19) & " ") & "(Ref: " & H19 & ") (Type: " & P19 & ") (BU: " & L19 & ") (Head: " & M19 & ")" & IF(ISBLANK(T19), "", " (Apt#: " & T19 & ")"))))) -> Fund Transfer: From YES MASTER 0264 to x0377 (Ref: ) (Type: Master 2 RERA) (BU: Casa Romana) (Head: Internal) | Y19: 128655.78 | Z19: =Y19-K19 -> 1.78
A20: 217 | B20: =IFERROR("Q"&(INT(MOD(C20-4,12)/3)+1),"") -> Q2 | C20: =IFERROR(MONTH(DATEVALUE(D20)),"") -> 8 | D20: 05-Aug-2026 | E20: 05-Aug-2026 | G20: NEFT CR-SBIN0003771-VIDYA DEVI -DWARKADHIS PROJECTS PVT L-SBIN526217498424 | J20: 61110 | K20: =K21+J20-I20 -> 360998 | L20: Casa Romana | M20: Collection | O20: Entry | P20: Customer Collection | Q20: Credit- no effect | T20: L-043 | V20: On Account | W20: =TRIM(IF(M20="Internal", IF(ISBLANK(G20), IF(LEN(G20)-LEN(SUBSTITUTE(G20,"-",""))>=3, "Fund Transfer: From x" & RIGHT(MID(G20, FIND("|", SUBSTITUTE(G20, "-", "|", 3)) + 1, LEN(G20)), 4) & " to YES MASTER 0264 (Ref: " & H20 & ") (Type: " & P20 & ") (BU: " & L20 & ") (Head: " & M20 & ")", "Fund Transfer: To YES MASTER 0264 (Ref: " & H20 & ") (Type: " & P20 & ") (BU: " & L20 & ") (Head: " & M20 & ")"), IF(LEN(G20)-LEN(SUBSTITUTE(G20,"-",""))>=3, "Fund Transfer: From YES MASTER 0264 to x" & RIGHT(MID(G20, FIND("|", SUBSTITUTE(G20, "-", "|", 3)) + 1, LEN(G20)), 4) & " (Ref: " & H20 & ") (Type: " & P20 & ") (BU: " & L20 & ") (Head: " & M20 & ")", "Fund Transfer: From YES MASTER 0264 (Ref: " & H20 & ") (Type: " & P20 & ") (BU: " & L20 & ") (Head: " & M20 & ")")), IF(NOT(ISBLANK(J20)), IF(P20="Customer Collection", "Receipt: For " & IF(ISBLANK(T20), "", "(Apt#: " & T20 & ") ") & "(Ref: " & H20 & ") (" & IF(ISNUMBER(SEARCH("NEFT",G20)), "NEFT:", IF(ISNUMBER(SEARCH("RTGS",G20)), "RTGS:", IF(ISNUMBER(SEARCH("IMPS",G20)), "IMPS:", ""))) & " " & IF(ISNUMBER(SEARCH("SOHNA ROAD", G20)), "", IFERROR(MID(G20, FIND("-", G20, FIND("-", G20) + 1) + 1, LEN(G20)), SUBSTITUTE(SUBSTITUTE(SUBSTITUTE(G20, "IMPS/", ""), "NEFT/", ""), "RTGS/", ""))) & ") (Type: " & P20 & ") (BU: " & L20 & ")", IF(LEN(G20)-LEN(SUBSTITUTE(G20,"-",""))>=3, "Receipt: From x" & RIGHT(MID(G20, FIND("|", SUBSTITUTE(G20, "-", "|", 3)) + 1, LEN(G20)), 4) & " towards " & IF(ISBLANK(U20), L20, U20) & IF(OR(L20="Cancellation", L20="Collection"), " Apt No " & T20, "") & " (Ref: " & H20 & ") (Type: " & P20 & ") (BU: " & L20 & ") (Head: " & M20 & ")" & IF(ISBLANK(T20), "", " (Apt#: " & T20 & ")"), "Receipt: Against " & IF(ISBLANK(U20), L20, U20) & IF(OR(L20="Cancellation", L20="Collection"), " Apt No " & T20, "") & " (Ref: " & H20 & ") (Type: " & P20 & ") (BU: " & L20 & ") (Head: " & M20 & ")" & IF(ISBLANK(T20), "", " (Apt#: " & T20 & ")"))), IF(LEN(G20)-LEN(SUBSTITUTE(G20,"-",""))>=3, "Payment: To x" & RIGHT(MID(G20, FIND("|", SUBSTITUTE(G20, "-", "|", 3)) + 1, LEN(G20)), 4) & " for " & IF(ISBLANK(U20), L20, U20) & " (Ref: " & H20 & ") (Type: " & P20 & ") (BU: " & L20 & ") (Head: " & M20 & ")" & IF(ISBLANK(T20), "", " (Apt#: " & T20 & ")"), "Payment: Disbursement for " & IF(ISBLANK(U20), "", IF(ISBLANK(U20), "", U20) & " ") & "(Ref: " & H20 & ") (Type: " & P20 & ") (BU: " & L20 & ") (Head: " & M20 & ")" & IF(ISBLANK(T20), "", " (Apt#: " & T20 & ")"))))) -> Receipt: For (Apt#: L-043) (Ref: ) (NEFT: VIDYA DEVI -DWARKADHIS PROJECTS PVT L-SBIN526217498424) (Type: Customer Collection) (BU: Casa Romana) | X20: 0.05 | Y20: 360999.78 | Z20: =Y20-K20 -> 1.78
A21: 216 | B21: =IFERROR("Q"&(INT(MOD(C21-4,12)/3)+1),"") -> Q2 | C21: =IFERROR(MONTH(DATEVALUE(D21)),"") -> 8 | D21: 05-Aug-2026 | E21: 05-Aug-2026 | G21: YIB-TPT-DWARKADHIS PROJECTS PRIVATE LIMITED-INTERNAL-0455632 00000377 | I21: 159227 | K21: =K22+J21-I21 -> 299888 | L21: Casa Romana | M21: Internal | O21: Entry | P21: Master 2 RERA | Q21: Internal transfer | W21: =TRIM(IF(M21="Internal", IF(ISBLANK(G21), IF(LEN(G21)-LEN(SUBSTITUTE(G21,"-",""))>=3, "Fund Transfer: From x" & RIGHT(MID(G21, FIND("|", SUBSTITUTE(G21, "-", "|", 3)) + 1, LEN(G21)), 4) & " to YES MASTER 0264 (Ref: " & H21 & ") (Type: " & P21 & ") (BU: " & L21 & ") (Head: " & M21 & ")", "Fund Transfer: To YES MASTER 0264 (Ref: " & H21 & ") (Type: " & P21 & ") (BU: " & L21 & ") (Head: " & M21 & ")"), IF(LEN(G21)-LEN(SUBSTITUTE(G21,"-",""))>=3, "Fund Transfer: From YES MASTER 0264 to x" & RIGHT(MID(G21, FIND("|", SUBSTITUTE(G21, "-", "|", 3)) + 1, LEN(G21)), 4) & " (Ref: " & H21 & ") (Type: " & P21 & ") (BU: " & L21 & ") (Head: " & M21 & ")", "Fund Transfer: From YES MASTER 0264 (Ref: " & H21 & ") (Type: " & P21 & ") (BU: " & L21 & ") (Head: " & M21 & ")")), IF(NOT(ISBLANK(J21)), IF(P21="Customer Collection", "Receipt: For " & IF(ISBLANK(T21), "", "(Apt#: " & T21 & ") ") & "(Ref: " & H21 & ") (" & IF(ISNUMBER(SEARCH("NEFT",G21)), "NEFT:", IF(ISNUMBER(SEARCH("RTGS",G21)), "RTGS:", IF(ISNUMBER(SEARCH("IMPS",G21)), "IMPS:", ""))) & " " & IF(ISNUMBER(SEARCH("SOHNA ROAD", G21)), "", IFERROR(MID(G21, FIND("-", G21, FIND("-", G21) + 1) + 1, LEN(G21)), SUBSTITUTE(SUBSTITUTE(SUBSTITUTE(G21, "IMPS/", ""), "NEFT/", ""), "RTGS/", ""))) & ") (Type: " & P21 & ") (BU: " & L21 & ")", IF(LEN(G21)-LEN(SUBSTITUTE(G21,"-",""))>=3, "Receipt: From x" & RIGHT(MID(G21, FIND("|", SUBSTITUTE(G21, "-", "|", 3)) + 1, LEN(G21)), 4) & " towards " & IF(ISBLANK(U21), L21, U21) & IF(OR(L21="Cancellation", L21="Collection"), " Apt No " & T21, "") & " (Ref: " & H21 & ") (Type: " & P21 & ") (BU: " & L21 & ") (Head: " & M21 & ")" & IF(ISBLANK(T21), "", " (Apt#: " & T21 & ")"), "Receipt: Against " & IF(ISBLANK(U21), L21, U21) & IF(OR(L21="Cancellation", L21="Collection"), " Apt No " & T21, "") & " (Ref: " & H21 & ") (Type: " & P21 & ") (BU: " & L21 & ") (Head: " & M21 & ")" & IF(ISBLANK(T21), "", " (Apt#: " & T21 & ")"))), IF(LEN(G21)-LEN(SUBSTITUTE(G21,"-",""))>=3, "Payment: To x" & RIGHT(MID(G21, FIND("|", SUBSTITUTE(G21, "-", "|", 3)) + 1, LEN(G21)), 4) & " for " & IF(ISBLANK(U21), L21, U21) & " (Ref: " & H21 & ") (Type: " & P21 & ") (BU: " & L21 & ") (Head: " & M21 & ")" & IF(ISBLANK(T21), "", " (Apt#: " & T21 & ")"), "Payment: Disbursement for " & IF(ISBLANK(U21), "", IF(ISBLANK(U21), "", U21) & " ") & "(Ref: " & H21 & ") (Type: " & P21 & ") (BU: " & L21 & ") (Head: " & M21 & ")" & IF(ISBLANK(T21), "", " (Apt#: " & T21 & ")"))))) -> Fund Transfer: From YES MASTER 0264 to x0377 (Ref: ) (Type: Master 2 RERA) (BU: Casa Romana) (Head: Internal) | Y21: 299889.78 | Z21: =Y21-K21 -> 1.78
A22: 215 | B22: =IFERROR("Q"&(INT(MOD(C22-4,12)/3)+1),"") -> Q2 | C22: =IFERROR(MONTH(DATEVALUE(D22)),"") -> 8 | D22: 05-Aug-2026 | E22: 05-Aug-2026 | G22: YIB-TPT-DWARKADHIS PROJECTS PVT LT D-INTERNAL-045563400002477 | I22: 68240 | K22: =K23+J22-I22 -> 459115 | L22: Casa Romana | M22: Internal | O22: Entry | P22: Master to Free | Q22: Internal transfer | W22: =TRIM(IF(M22="Internal", IF(ISBLANK(G22), IF(LEN(G22)-LEN(SUBSTITUTE(G22,"-",""))>=3, "Fund Transfer: From x" & RIGHT(MID(G22, FIND("|", SUBSTITUTE(G22, "-", "|", 3)) + 1, LEN(G22)), 4) & " to YES MASTER 0264 (Ref: " & H22 & ") (Type: " & P22 & ") (BU: " & L22 & ") (Head: " & M22 & ")", "Fund Transfer: To YES MASTER 0264 (Ref: " & H22 & ") (Type: " & P22 & ") (BU: " & L22 & ") (Head: " & M22 & ")"), IF(LEN(G22)-LEN(SUBSTITUTE(G22,"-",""))>=3, "Fund Transfer: From YES MASTER 0264 to x" & RIGHT(MID(G22, FIND("|", SUBSTITUTE(G22, "-", "|", 3)) + 1, LEN(G22)), 4) & " (Ref: " & H22 & ") (Type: " & P22 & ") (BU: " & L22 & ") (Head: " & M22 & ")", "Fund Transfer: From YES MASTER 0264 (Ref: " & H22 & ") (Type: " & P22 & ") (BU: " & L22 & ") (Head: " & M22 & ")")), IF(NOT(ISBLANK(J22)), IF(P22="Customer Collection", "Receipt: For " & IF(ISBLANK(T22), "", "(Apt#: " & T22 & ") ") & "(Ref: " & H22 & ") (" & IF(ISNUMBER(SEARCH("NEFT",G22)), "NEFT:", IF(ISNUMBER(SEARCH("RTGS",G22)), "RTGS:", IF(ISNUMBER(SEARCH("IMPS",G22)), "IMPS:", ""))) & " " & IF(ISNUMBER(SEARCH("SOHNA ROAD", G22)), "", IFERROR(MID(G22, FIND("-", G22, FIND("-", G22) + 1) + 1, LEN(G22)), SUBSTITUTE(SUBSTITUTE(SUBSTITUTE(G22, "IMPS/", ""), "NEFT/", ""), "RTGS/", ""))) & ") (Type: " & P22 & ") (BU: " & L22 & ")", IF(LEN(G22)-LEN(SUBSTITUTE(G22,"-",""))>=3, "Receipt: From x" & RIGHT(MID(G22, FIND("|", SUBSTITUTE(G22, "-", "|", 3)) + 1, LEN(G22)), 4) & " towards " & IF(ISBLANK(U22), L22, U22) & IF(OR(L22="Cancellation", L22="Collection"), " Apt No " & T22, "") & " (Ref: " & H22 & ") (Type: " & P22 & ") (BU: " & L22 & ") (Head: " & M22 & ")" & IF(ISBLANK(T22), "", " (Apt#: " & T22 & ")"), "Receipt: Against " & IF(ISBLANK(U22), L22, U22) & IF(OR(L22="Cancellation", L22="Collection"), " Apt No " & T22, "") & " (Ref: " & H22 & ") (Type: " & P22 & ") (BU: " & L22 & ") (Head: " & M22 & ")" & IF(ISBLANK(T22), "", " (Apt#: " & T22 & ")"))), IF(LEN(G22)-LEN(SUBSTITUTE(G22,"-",""))>=3, "Payment: To x" & RIGHT(MID(G22, FIND("|", SUBSTITUTE(G22, "-", "|", 3)) + 1, LEN(G22)), 4) & " for " & IF(ISBLANK(U22), L22, U22) & " (Ref: " & H22 & ") (Type: " & P22 & ") (BU: " & L22 & ") (Head: " & M22 & ")" & IF(ISBLANK(T22), "", " (Apt#: " & T22 & ")"), "Payment: Disbursement for " & IF(ISBLANK(U22), "", IF(ISBLANK(U22), "", U22) & " ") & "(Ref: " & H22 & ") (Type: " & P22 & ") (BU: " & L22 & ") (Head: " & M22 & ")" & IF(ISBLANK(T22), "", " (Apt#: " & T22 & ")"))))) -> Fund Transfer: From YES MASTER 0264 to x2477 (Ref: ) (Type: Master to Free) (BU: Casa Romana) (Head: Internal) | Y22: 459116.78 | Z22: =Y22-K22 -> 1.78
A23: 214 | B23: =IFERROR("Q"&(INT(MOD(C23-4,12)/3)+1),"") -> Q2 | C23: =IFERROR(MONTH(DATEVALUE(D23)),"") -> 8 | D23: 04-Aug-2026 | E23: 04-Aug-2026 | G23: NEFT CR-ICIC0SF0002-POONAM K AUR-DWARKADHIS PROJECTS PRIVA-IN12621649590896 | J23: 100000 | K23: =K24+J23-I23 -> 527355 | L23: Casa Romana | M23: Collection | O23: Entry | P23: Customer Collection | Q23: Credit- no effect | T23: U-092 | V23: Adjust 31,245 On Account 68,755 | W23: =TRIM(IF(M23="Internal", IF(ISBLANK(G23), IF(LEN(G23)-LEN(SUBSTITUTE(G23,"-",""))>=3, "Fund Transfer: From x" & RIGHT(MID(G23, FIND("|", SUBSTITUTE(G23, "-", "|", 3)) + 1, LEN(G23)), 4) & " to YES MASTER 0264 (Ref: " & H23 & ") (Type: " & P23 & ") (BU: " & L23 & ") (Head: " & M23 & ")", "Fund Transfer: To YES MASTER 0264 (Ref: " & H23 & ") (Type: " & P23 & ") (BU: " & L23 & ") (Head: " & M23 & ")"), IF(LEN(G23)-LEN(SUBSTITUTE(G23,"-",""))>=3, "Fund Transfer: From YES MASTER 0264 to x" & RIGHT(MID(G23, FIND("|", SUBSTITUTE(G23, "-", "|", 3)) + 1, LEN(G23)), 4) & " (Ref: " & H23 & ") (Type: " & P23 & ") (BU: " & L23 & ") (Head: " & M23 & ")", "Fund Transfer: From YES MASTER 0264 (Ref: " & H23 & ") (Type: " & P23 & ") (BU: " & L23 & ") (Head: " & M23 & ")")), IF(NOT(ISBLANK(J23)), IF(P23="Customer Collection", "Receipt: For " & IF(ISBLANK(T23), "", "(Apt#: " & T23 & ") ") & "(Ref: " & H23 & ") (" & IF(ISNUMBER(SEARCH("NEFT",G23)), "NEFT:", IF(ISNUMBER(SEARCH("RTGS",G23)), "RTGS:", IF(ISNUMBER(SEARCH("IMPS",G23)), "IMPS:", ""))) & " " & IF(ISNUMBER(SEARCH("SOHNA ROAD", G23)), "", IFERROR(MID(G23, FIND("-", G23, FIND("-", G23) + 1) + 1, LEN(G23)), SUBSTITUTE(SUBSTITUTE(SUBSTITUTE(G23, "IMPS/", ""), "NEFT/", ""), "RTGS/", ""))) & ") (Type: " & P23 & ") (BU: " & L23 & ")", IF(LEN(G23)-LEN(SUBSTITUTE(G23,"-",""))>=3, "Receipt: From x" & RIGHT(MID(G23, FIND("|", SUBSTITUTE(G23, "-", "|", 3)) + 1, LEN(G23)), 4) & " towards " & IF(ISBLANK(U23), L23, U23) & IF(OR(L23="Cancellation", L23="Collection"), " Apt No " & T23, "") & " (Ref: " & H23 & ") (Type: " & P23 & ") (BU: " & L23 & ") (Head: " & M23 & ")" & IF(ISBLANK(T23), "", " (Apt#: " & T23 & ")"), "Receipt: Against " & IF(ISBLANK(U23), L23, U23) & IF(OR(L23="Cancellation", L23="Collection"), " Apt No " & T23, "") & " (Ref: " & H23 & ") (Type: " & P23 & ") (BU: " & L23 & ") (Head: " & M23 & ")" & IF(ISBLANK(T23), "", " (Apt#: " & T23 & ")"))), IF(LEN(G23)-LEN(SUBSTITUTE(G23,"-",""))>=3, "Payment: To x" & RIGHT(MID(G23, FIND("|", SUBSTITUTE(G23, "-", "|", 3)) + 1, LEN(G23)), 4) & " for " & IF(ISBLANK(U23), L23, U23) & " (Ref: " & H23 & ") (Type: " & P23 & ") (BU: " & L23 & ") (Head: " & M23 & ")" & IF(ISBLANK(T23), "", " (Apt#: " & T23 & ")"), "Payment: Disbursement for " & IF(ISBLANK(U23), "", IF(ISBLANK(U23), "", U23) & " ") & "(Ref: " & H23 & ") (Type: " & P23 & ") (BU: " & L23 & ") (Head: " & M23 & ")" & IF(ISBLANK(T23), "", " (Apt#: " & T23 & ")"))))) -> Receipt: For (Apt#: U-092) (Ref: ) (NEFT: POONAM K AUR-DWARKADHIS PROJECTS PRIVA-IN12621649590896) (Type: Customer Collection) (BU: Casa Romana) | Y23: 527356.78 | Z23: =Y23-K23 -> 1.78 | AB23: ok
